(dp1
S'output'
p2
S'<type \'exceptions.RuntimeError\'> Failure to connect, tried 5 times:\nTraceback (most recent call last):\n  File "/Users/Brandon/Develop/ipo_web2py/gluon/packages/dal/pydal/base.py", line 446, in __init__\n    self._adapter = ADAPTERS[self._dbname](**kwargs)\n  File "/Users/Brandon/Develop/ipo_web2py/gluon/packages/dal/pydal/adapters/base.py", line 60, in __call__\n    obj = super(AdapterMeta, cls).__call__(*args, **kwargs)\n  File "/Users/Brandon/Develop/ipo_web2py/gluon/packages/dal/pydal/adapters/postgres.py", line 155, in __init__\n    self.reconnect()\n  File "/Users/Brandon/Develop/ipo_web2py/gluon/packages/dal/pydal/connection.py", line 125, in reconnect\n    self.connection = f()\n  File "/Users/Brandon/Develop/ipo_web2py/gluon/packages/dal/pydal/adapters/postgres.py", line 152, in connector\n    return self.driver.connect(**driver_args)\n  File "/Users/Brandon/Develop/ipo_web2py/gluon/contrib/pg8000/__init__.py", line 336, in connect\n    user, host, unix_sock, port, database, password, ssl)\n  File "/Users/Brandon/Develop/ipo_web2py/gluon/contrib/pg8000/core.py", line 1282, in __init__\n    raise self.error\nProgrammingError: (\'FATAL\', \'3D000\', \'database "IPOS" does not exist\')\n'
p3
sS'layer'
p4
S'/Users/Brandon/Develop/ipo_web2py/applications/ipos/models/0_db.py'
p5
sS'code'
p6
S'\nif request.global_settings.web2py_version < "2.14.1":\n    raise HTTP(500, "Requires web2py 2.13.3 or newer")\n\n# -------------------------------------------------------------------------\n# if SSL/HTTPS is properly configured and you want all HTTP requests to\n# be redirected to HTTPS, uncomment the line below:\n# -------------------------------------------------------------------------\n# request.requires_https()\n\n# -------------------------------------------------------------------------\n# app configuration made easy. Look inside private/appconfig.ini\n# -------------------------------------------------------------------------\nfrom gluon.contrib.appconfig import AppConfig\n\n# -------------------------------------------------------------------------\n# once in production, remove reload=True to gain full speed\n# -------------------------------------------------------------------------\nmyconf = AppConfig(reload=True)\ndb = DAL(myconf.get(\'db.uri\'), myconf.get(\'db.pool_size\'),lazy_tables=myconf.get(\'db.lazy_tables\'))\n'
p7
sS'snapshot'
p8
(dp9
sS'traceback'
p10
S'Traceback (most recent call last):\n  File "/Users/Brandon/Develop/ipo_web2py/gluon/restricted.py", line 227, in restricted\n    exec ccode in environment\n  File "/Users/Brandon/Develop/ipo_web2py/applications/ipos/models/0_db.py", line 20, in <module>\n    db = DAL(myconf.get(\'db.uri\'), myconf.get(\'db.pool_size\'),lazy_tables=myconf.get(\'db.lazy_tables\'))\n  File "/Users/Brandon/Develop/ipo_web2py/gluon/packages/dal/pydal/base.py", line 174, in __call__\n    obj = super(MetaDAL, cls).__call__(*args, **kwargs)\n  File "/Users/Brandon/Develop/ipo_web2py/gluon/packages/dal/pydal/base.py", line 473, in __init__\n    "Failure to connect, tried %d times:\\n%s" % (attempts, tb)\nRuntimeError: Failure to connect, tried 5 times:\nTraceback (most recent call last):\n  File "/Users/Brandon/Develop/ipo_web2py/gluon/packages/dal/pydal/base.py", line 446, in __init__\n    self._adapter = ADAPTERS[self._dbname](**kwargs)\n  File "/Users/Brandon/Develop/ipo_web2py/gluon/packages/dal/pydal/adapters/base.py", line 60, in __call__\n    obj = super(AdapterMeta, cls).__call__(*args, **kwargs)\n  File "/Users/Brandon/Develop/ipo_web2py/gluon/packages/dal/pydal/adapters/postgres.py", line 155, in __init__\n    self.reconnect()\n  File "/Users/Brandon/Develop/ipo_web2py/gluon/packages/dal/pydal/connection.py", line 125, in reconnect\n    self.connection = f()\n  File "/Users/Brandon/Develop/ipo_web2py/gluon/packages/dal/pydal/adapters/postgres.py", line 152, in connector\n    return self.driver.connect(**driver_args)\n  File "/Users/Brandon/Develop/ipo_web2py/gluon/contrib/pg8000/__init__.py", line 336, in connect\n    user, host, unix_sock, port, database, password, ssl)\n  File "/Users/Brandon/Develop/ipo_web2py/gluon/contrib/pg8000/core.py", line 1282, in __init__\n    raise self.error\nProgrammingError: (\'FATAL\', \'3D000\', \'database "IPOS" does not exist\')\n\n'
p11
s.